Workbook

Sheet Instrucciones
A1: Comparativo de propuestas – Agencia Integral Evento Bariloche 2027
A3: Uso | B3: Completar una columna por agencia con lo que declara en su propuesta. El pliego (punto 4.1) pide estos datos; si una agencia no los informa, dejar la celda vacía y anotarlo en Comentarios.
A4: Celdas amarillas | B4: Datos a completar (nombre de la agencia, cantidades, medidas, montos, puntajes).
A5: Celdas grises | B5: Se calculan solas: total de staff, superficie de carpa y escenario, total de LED, totales de costos, puntaje y ranking.
A6: Texto en rojo | B6: La agencia declara menos que el mínimo del pliego, o "No" donde el pliego pide "Sí".
A7: Hoja Comparativo técnico | B7: Staff por rubro, medidas, m² de LED, cantidades de gráfica, equipamiento y condiciones comerciales.
A8: Hoja Costos | B8: Subtotal por rubro según la apertura del punto 4.2 del pliego, fee, total, costo por participante y diferencia vs. la oferta más baja.
A9: Hoja Evaluación | B9: Puntaje de 1 a 5 por criterio con pesos ajustables. El precio se puntúa automáticamente desde la hoja Costos.
A11: Ejemplo de carga (valores ilustrativos)
A12: Ítem | B12: Unidad | C12: Pedido en pliego | D12: Agencia 1
A13: Escenario: ancho | B13: m | D13: 16
A14: Escenario: profundidad | B14: m | D14: 10
A15: Escenario: superficie | B15: m² | D15: =D13*D14 -> 160
A16: Pantalla LED fondo de escenario | B16: m² | D16: 72
A17: Traducción simultánea: receptores | B17: unidades | C17: 15 | D17: 15

Sheet Comparativo técnico
A1: Comparativo técnico de propuestas – Agencia Integral Evento Bariloche 2027
A2: Completar las celdas amarillas con lo que declara cada agencia. Las celdas grises se calculan solas. La columna "Pedido en pliego" indica el mínimo o la referencia del pliego.
A4: Punto | B4: Ítem a describir por la agencia | C4: Unidad | D4: Pedido en pliego | E4: Agencia 1 | F4: Agencia 2 | G4: Agencia 3 | H4: Agencia 4 | I4: Comentarios VW
B5: Nombre de la agencia
A6: 3.1 Staff y coordinación
A7: 3.1 | B7: Project Manager | C7: personas | D7: 1
A8: 3.1 | B8: Productor general | C8: personas
A9: 3.1 | B9: Coordinadores de aéreos y traslados | C9: personas
A10: 3.1 | B10: Coordinadores de hotel y acreditación | C10: personas
A11: 3.1 | B11: Coordinadores de show y técnica (incluye stage manager) | C11: personas
A12: 3.1 | B12: Coordinadores de test drive | C12: personas
A13: 3.1 / 3.18 | B13: Coordinadores de prensa | C13: personas
A14: 3.1 | B14: Azafatas y anfitriones | C14: personas
A15: 3.6 / 3.7 | B15: Técnicos y operadores (sonido, luces, LED, video) | C15: personas
A16: 3.17 | B16: Personal de carga, descarga y utilería | C16: personas
A17: 3.17 | B17: Seguridad y serenos | C17: personas
A18: 3.1 | B18: Otros (detallar en comentarios) | C18: personas
A19: 3.1 | B19: TOTAL STAFF | C19: personas | E19: =SUM(E7:E18) -> 0 | F19: =SUM(F7:F18) -> 0 | G19: =SUM(G7:G18) -> 0 | H19: =SUM(H7:H18) -> 0
A20: 3.1 | B20: Staff en Aeroparque (ida) | C20: personas
A21: 3.1 | B21: Staff en aeropuerto de Bariloche (arribo) | C21: personas
A22: 3.1 | B22: Staff asignado al grupo prensa (día 2) | C22: personas
A23: 3.1 | B23: Staff asignado al grupo concesionarios (día 2) | C23: personas
A24: 3.1 | B24: Experiencia del Project Manager | C24: años
A25: 3.3 Plataforma de acreditación, registro y check-in
A26: 3.3 | B26: Tipo de plataforma (web, app o ambas) | C26: texto | D26: Web o app
A27: 3.3 | B27: Desarrollo propio o licencia de terceros | C27: texto
A28: 3.3 | B28: Check-in con QR | C28: sí/no | D28: Sí
A29: 3.3 | B29: Agenda personal por invitado (grupo y tanda de test drive) | C29: sí/no | D29: Sí
A30: 3.3 | B30: Panel de seguimiento en tiempo real para VW | C30: sí/no | D30: Sí
A31: 3.3 | B31: Puestos de acreditación (AEP + resort) | C31: puestos
A32: 3.3 | B32: Impresoras de credenciales en el lugar | C32: unidades
A33: 3.3 | B33: Demo disponible para VW | C33: sí/no | D33: Sí
A34: 3.4 Identidad de marca y branding
A35: 3.4 | B35: Cantidad total de piezas gráficas | C35: piezas
A36: 3.4 | B36: Superficie total de gráfica | C36: m²
A37: 3.4 | B37: Piezas en aeropuertos (AEP y BRC) | C37: piezas
A38: 3.4 | B38: Piezas de señalética | C38: piezas
A39: 3.4 | B39: Buses brandeados | C39: unidades
A40: 3.4 | B40: Espacios de photo opportunity | C40: unidades | D40: 2
A41: 3.4 | B41: Logos corpóreos | C41: unidades | D41: 5
...

Sheet Costos
A1: Comparativo económico por rubro (ARS, IVA incluido)
A2: Cargar el subtotal de cada rubro según la cotización de cada agencia, respetando la apertura del punto 4.2 del pliego.
A3: Participantes | B3: 205 | C3: 195 invitados + 10 staff VW (dato del pliego)
A5: Rubro | B5: Punto | C5: Agencia 1 | D5: Agencia 2 | E5: Agencia 3 | F5: Agencia 4
A6: Nombre de la agencia | C6: =IF('Comparativo técnico'!E5="","",'Comparativo técnico'!E5) | D6: =IF('Comparativo técnico'!F5="","",'Comparativo técnico'!F5) | E6: =IF('Comparativo técnico'!G5="","",'Comparativo técnico'!G5) | F6: =IF('Comparativo técnico'!H5="","",'Comparativo técnico'!H5)
A7: Staff y coordinación (incluye pasajes, alojamiento y viáticos del staff) | B7: 3.1 / 3.2
A8: Plataforma de acreditación, registro y gestión de invitados | B8: 3.3
A9: Identidad de marca y branding | B9: 3.4
A10: Ambientación | B10: 3.5
A11: Carpa, show de develación, escenario y plataforma giratoria | B11: 3.6
A12: Técnica general, técnica de la cena del día 2 y traducción simultánea | B12: 3.7 / 3.8
A13: Infraestructura y servicios no incluidos por el hotel | B13: 3.9
A14: Exhibición, iluminación y limpieza de unidades | B14: 3.10 / 3.11
A15: Presentaciones y contenido | B15: 3.12
A16: Foto y video | B16: 3.13
A17: Kits de bienvenida y regalos | B17: 3.14
A18: Buses y traslados | B18: 3.15
... A21: Atención de prensa | B21: 3.18
A22: Subtotal producción | C22: =SUM(C7:C21) -> 0 | D22: =SUM(D7:D21) -> 0 | E22: =SUM(E7:E21) -> 0 | F22: =SUM(F7:F21) -> 0
A23: Fee de agencia (%) | C23: ='Comparativo técnico'!E137 -> 0 | D23: ='Comparativo técnico'!F137 -> 0 | E23: ='Comparativo técnico'!G137 -> 0 | F23: ='Comparativo técnico'!H137 -> 0
A24: Fee de agencia ($) | C24: =C22*C23 -> 0 | D24: =D22*D23 -> 0 | E24: =E22*E23 -> 0 | F24: =F22*F23 -> 0
A25: TOTAL | C25: =C22+C24 -> 0 | D25: =D22+D24 -> 0 | E25: =E22+E24 -> 0 | F25: =F22+F24 -> 0
A26: Costo por participante | C26: =IF(C25>0,C25/$B$3,"") | D26: =IF(D25>0,D25/$B$3,"") | E26: =IF(E25>0,E25/$B$3,"") | F26: =IF(F25>0,F25/$B$3,"")
A27: Diferencia vs. la oferta más baja | C27: {=IF(C25>0,C25/MIN(IF($C$25:$F$25>0,$C$25:$F$25))-1,"")} | D27: {=IF(D25>0,D25/MIN(IF($C$25:$F$25>0,$C$25:$F$25))-1,"")} | E27: {=IF(E25>0,E25/MIN(IF($C$25:$F$25>0,$C$25:$F$25))-1,"")} | F27: {=IF(F25>0,F25/MIN(IF($C$25:$F$25>0,$C$25:$F$25))-1,"")}
A28: Ranking de precio (1 = más barata) | C28: =IF(C25>0,COUNTIFS($C$25:$F$25,">0",$C$25:$F$25,"<"&C25)+1,"") | D28: =IF(D25>0,COUNTIFS($C$25:$F$25,">0",$C$25:$F$25,"<"&D25)+1,"") | E28: =IF(E25>0,COUNTIFS($C$25:$F$25,">0",$C$25:$F$25,"<"&E25)+1,"") | F28: =IF(F25>0,COUNTIFS($C$25:$F$25,">0",$C$25:$F$25,"<"&F25)+1,"")
A30: Opcionales (no suman al total)
A31: Valet en Aeroparque | B31: –
A32: Otros opcionales propuestos (detallar) | B32: –

Sheet Evaluación
A1: Evaluación ponderada de propuestas
A2: Puntaje de 1 (malo) a 5 (excelente) por criterio. Los pesos se pueden ajustar y deben sumar 100%. El precio se puntúa solo: 5 para la oferta más baja y proporcional para el resto.
A4: Criterio | B4: Peso | C4: Agencia 1 | D4: Agencia 2 | E4: Agencia 3 | F4: Agencia 4
A5: Nombre de la agencia | C5: =IF('Comparativo técnico'!E5="","",'Comparativo técnico'!E5) | D5: =IF('Comparativo técnico'!F5="","",'Comparativo técnico'!F5) | E5: =IF('Comparativo técnico'!G5="","",'Comparativo técnico'!G5) | F5: =IF('Comparativo técnico'!H5="","",'Comparativo técnico'!H5)
A6: Propuesta creativa y concepto del show de develación | B6: 0.2
A7: Escenografía, técnica y pantallas (escala e impacto) | B7: 0.15
A8: Estructura de staff y operación (aeropuertos, traslados, grupos) | B8: 0.15
A9: Plataforma de acreditación, registro y check-in | B9: 0.1
A10: Antecedentes y experiencia en lanzamientos similares | B10: 0.1
A11: Precio | B11: 0.3 | C11: {=IF(Costos!C25>0,5*MIN(IF(Costos!$C$25:$F$25>0,Costos!$C$25:$F$25))/Costos!C25,"")} | D11: {=IF(Costos!D25>0,5*MIN(IF(Costos!$C$25:$F$25>0,Costos!$C$25:$F$25))/Costos!D25,"")} | E11: {=IF(Costos!E25>0,5*MIN(IF(Costos!$C$25:$F$25>0,Costos!$C$25:$F$25))/Costos!E25,"")} | F11: {=IF(Costos!F25>0,5*MIN(IF(Costos!$C$25:$F$25>0,Costos!$C$25:$F$25))/Costos!F25,"")}
A12: Suma de pesos (debe ser 100%) | B12: =SUM(B6:B11) -> 1
A13: PUNTAJE PONDERADO (sobre 5) | C13: =IF(COUNT(C6:C11)=0,"",SUMPRODUCT($B$6:$B$11,C6:C11)) | D13: =IF(COUNT(D6:D11)=0,"",SUMPRODUCT($B$6:$B$11,D6:D11)) | E13: =IF(COUNT(E6:E11)=0,"",SUMPRODUCT($B$6:$B$11,E6:E11)) | F13: =IF(COUNT(F6:F11)=0,"",SUMPRODUCT($B$6:$B$11,F6:F11))
A14: Ranking (1 = mejor) | C14: =IF(C13="","",COUNTIF($C$13:$F$13,">"&C13)+1) | D14: =IF(D13="","",COUNTIF($C$13:$F$13,">"&D13)+1) | E14: =IF(E13="","",COUNTIF($C$13:$F$13,">"&E13)+1) | F14: =IF(F13="","",COUNTIF($C$13:$F$13,">"&F13)+1)
